2018-09-04 16:08:31,582 ERROR: Exception on /edit_profile [POST] [in /home/yoj/devman/microblog/.venv/lib/python3.6/site-packages/flask/app.py:1761]
Traceback (most recent call last):
  File "/home/yoj/devman/microblog/.venv/lib/python3.6/site-packages/flask/app.py", line 2292, in wsgi_app
    response = self.full_dispatch_request()
  File "/home/yoj/devman/microblog/.venv/lib/python3.6/site-packages/flask/app.py", line 1815, in full_dispatch_request
    rv = self.handle_user_exception(e)
  File "/home/yoj/devman/microblog/.venv/lib/python3.6/site-packages/flask/app.py", line 1718, in handle_user_exception
    reraise(exc_type, exc_value, tb)
  File "/home/yoj/devman/microblog/.venv/lib/python3.6/site-packages/flask/_compat.py", line 35, in reraise
    raise value
  File "/home/yoj/devman/microblog/.venv/lib/python3.6/site-packages/flask/app.py", line 1813, in full_dispatch_request
    rv = self.dispatch_request()
  File "/home/yoj/devman/microblog/.venv/lib/python3.6/site-packages/flask/app.py", line 1799, in dispatch_request
    return self.view_functions[rule.endpoint](**req.view_args)
  File "/home/yoj/devman/microblog/.venv/lib/python3.6/site-packages/flask_login/utils.py", line 261, in decorated_view
    return func(*args, **kwargs)
  File "/home/yoj/devman/microblog/app/routes.py", line 143, in edit_profile
    photo.save(os.path.join(app.config['UPLOAD_FOLDER'], '/static/avatars/', filename))
  File "/home/yoj/devman/microblog/.venv/lib/python3.6/site-packages/werkzeug/datastructures.py", line 2725, in save
    dst = open(dst, 'wb')
FileNotFoundError: [Errno 2] No such file or directory: '/static/avatars/megacat.jpg'
2018-09-04 16:09:33,007 INFO: Microblog startup [in /home/yoj/devman/microblog/app/__init__.py:59]
2018-09-04 16:09:44,862 ERROR: Exception on /edit_profile [POST] [in /home/yoj/devman/microblog/.venv/lib/python3.6/site-packages/flask/app.py:1761]
Traceback (most recent call last):
  File "/home/yoj/devman/microblog/.venv/lib/python3.6/site-packages/flask/app.py", line 2292, in wsgi_app
    response = self.full_dispatch_request()
  File "/home/yoj/devman/microblog/.venv/lib/python3.6/site-packages/flask/app.py", line 1815, in full_dispatch_request
    rv = self.handle_user_exception(e)
  File "/home/yoj/devman/microblog/.venv/lib/python3.6/site-packages/flask/app.py", line 1718, in handle_user_exception
    reraise(exc_type, exc_value, tb)
  File "/home/yoj/devman/microblog/.venv/lib/python3.6/site-packages/flask/_compat.py", line 35, in reraise
    raise value
  File "/home/yoj/devman/microblog/.venv/lib/python3.6/site-packages/flask/app.py", line 1813, in full_dispatch_request
    rv = self.dispatch_request()
  File "/home/yoj/devman/microblog/.venv/lib/python3.6/site-packages/flask/app.py", line 1799, in dispatch_request
    return self.view_functions[rule.endpoint](**req.view_args)
  File "/home/yoj/devman/microblog/.venv/lib/python3.6/site-packages/flask_login/utils.py", line 261, in decorated_view
    return func(*args, **kwargs)
  File "/home/yoj/devman/microblog/app/routes.py", line 143, in edit_profile
    photo.save(os.path.join(app.config['UPLOAD_FOLDER'], '/static/avatars/', filename))
  File "/home/yoj/devman/microblog/.venv/lib/python3.6/site-packages/werkzeug/datastructures.py", line 2725, in save
    dst = open(dst, 'wb')
FileNotFoundError: [Errno 2] No such file or directory: '/static/avatars/megacat.jpg'
2018-09-04 16:13:18,703 INFO: Microblog startup [in /home/yoj/devman/microblog/app/__init__.py:59]
2018-09-04 16:14:55,163 INFO: Microblog startup [in /home/yoj/devman/microblog/app/__init__.py:59]
2018-09-04 16:15:17,959 ERROR: Exception on /edit_profile [POST] [in /home/yoj/devman/microblog/.venv/lib/python3.6/site-packages/flask/app.py:1761]
Traceback (most recent call last):
  File "/home/yoj/devman/microblog/.venv/lib/python3.6/site-packages/flask/app.py", line 2292, in wsgi_app
    response = self.full_dispatch_request()
  File "/home/yoj/devman/microblog/.venv/lib/python3.6/site-packages/flask/app.py", line 1815, in full_dispatch_request
    rv = self.handle_user_exception(e)
  File "/home/yoj/devman/microblog/.venv/lib/python3.6/site-packages/flask/app.py", line 1718, in handle_user_exception
    reraise(exc_type, exc_value, tb)
  File "/home/yoj/devman/microblog/.venv/lib/python3.6/site-packages/flask/_compat.py", line 35, in reraise
    raise value
  File "/home/yoj/devman/microblog/.venv/lib/python3.6/site-packages/flask/app.py", line 1813, in full_dispatch_request
    rv = self.dispatch_request()
  File "/home/yoj/devman/microblog/.venv/lib/python3.6/site-packages/flask/app.py", line 1799, in dispatch_request
    return self.view_functions[rule.endpoint](**req.view_args)
  File "/home/yoj/devman/microblog/.venv/lib/python3.6/site-packages/flask_login/utils.py", line 261, in decorated_view
    return func(*args, **kwargs)
  File "/home/yoj/devman/microblog/app/routes.py", line 143, in edit_profile
    photo.save(os.path.join(app.config['UPLOAD_FOLDER'], '/static/avatars/', filename))
  File "/home/yoj/devman/microblog/.venv/lib/python3.6/site-packages/werkzeug/datastructures.py", line 2725, in save
    dst = open(dst, 'wb')
FileNotFoundError: [Errno 2] No such file or directory: '/static/avatars/pes.jpg'
2018-09-04 16:17:18,419 INFO: Microblog startup [in /home/yoj/devman/microblog/app/__init__.py:59]
2018-09-04 16:17:30,238 ERROR: Exception on /edit_profile [POST] [in /home/yoj/devman/microblog/.venv/lib/python3.6/site-packages/flask/app.py:1761]
Traceback (most recent call last):
  File "/home/yoj/devman/microblog/.venv/lib/python3.6/site-packages/flask/app.py", line 2292, in wsgi_app
    response = self.full_dispatch_request()
  File "/home/yoj/devman/microblog/.venv/lib/python3.6/site-packages/flask/app.py", line 1815, in full_dispatch_request
    rv = self.handle_user_exception(e)
  File "/home/yoj/devman/microblog/.venv/lib/python3.6/site-packages/flask/app.py", line 1718, in handle_user_exception
    reraise(exc_type, exc_value, tb)
  File "/home/yoj/devman/microblog/.venv/lib/python3.6/site-packages/flask/_compat.py", line 35, in reraise
    raise value
  File "/home/yoj/devman/microblog/.venv/lib/python3.6/site-packages/flask/app.py", line 1813, in full_dispatch_request
    rv = self.dispatch_request()
  File "/home/yoj/devman/microblog/.venv/lib/python3.6/site-packages/flask/app.py", line 1799, in dispatch_request
    return self.view_functions[rule.endpoint](**req.view_args)
  File "/home/yoj/devman/microblog/.venv/lib/python3.6/site-packages/flask_login/utils.py", line 261, in decorated_view
    return func(*args, **kwargs)
  File "/home/yoj/devman/microblog/app/routes.py", line 143, in edit_profile
    photo.save(os.path.join(app.config['UPLOAD_FOLDER'], '/static/avatars/', filename))
  File "/home/yoj/devman/microblog/.venv/lib/python3.6/site-packages/werkzeug/datastructures.py", line 2725, in save
    dst = open(dst, 'wb')
FileNotFoundError: [Errno 2] No such file or directory: '/static/avatars/pes.jpg'
2018-09-04 16:18:01,987 INFO: Microblog startup [in /home/yoj/devman/microblog/app/__init__.py:59]
2018-09-04 16:18:12,537 ERROR: Exception on /edit_profile [POST] [in /home/yoj/devman/microblog/.venv/lib/python3.6/site-packages/flask/app.py:1761]
Traceback (most recent call last):
  File "/home/yoj/devman/microblog/.venv/lib/python3.6/site-packages/flask/app.py", line 2292, in wsgi_app
    response = self.full_dispatch_request()
  File "/home/yoj/devman/microblog/.venv/lib/python3.6/site-packages/flask/app.py", line 1815, in full_dispatch_request
    rv = self.handle_user_exception(e)
  File "/home/yoj/devman/microblog/.venv/lib/python3.6/site-packages/flask/app.py", line 1718, in handle_user_exception
    reraise(exc_type, exc_value, tb)
  File "/home/yoj/devman/microblog/.venv/lib/python3.6/site-packages/flask/_compat.py", line 35, in reraise
    raise value
  File "/home/yoj/devman/microblog/.venv/lib/python3.6/site-packages/flask/app.py", line 1813, in full_dispatch_request
    rv = self.dispatch_request()
  File "/home/yoj/devman/microblog/.venv/lib/python3.6/site-packages/flask/app.py", line 1799, in dispatch_request
    return self.view_functions[rule.endpoint](**req.view_args)
  File "/home/yoj/devman/microblog/.venv/lib/python3.6/site-packages/flask_login/utils.py", line 261, in decorated_view
    return func(*args, **kwargs)
  File "/home/yoj/devman/microblog/app/routes.py", line 143, in edit_profile
    photo.save(os.path.join(app.config['UPLOAD_FOLDER'], '/static/avatars/', filename))
  File "/home/yoj/devman/microblog/.venv/lib/python3.6/site-packages/werkzeug/datastructures.py", line 2725, in save
    dst = open(dst, 'wb')
FileNotFoundError: [Errno 2] No such file or directory: '/static/avatars/pes.jpg'
2018-09-04 16:21:51,812 INFO: Microblog startup [in /home/yoj/devman/microblog/app/__init__.py:59]
2018-09-04 16:35:58,130 INFO: Microblog startup [in /home/yoj/devman/microblog/app/__init__.py:59]
2018-09-04 16:44:31,706 INFO: Microblog startup [in /home/yoj/devman/microblog/app/__init__.py:59]
2018-09-04 16:45:30,144 INFO: Microblog startup [in /home/yoj/devman/microblog/app/__init__.py:59]
2018-09-04 16:46:51,106 INFO: Microblog startup [in /home/yoj/devman/microblog/app/__init__.py:59]
2018-09-04 17:14:33,188 INFO: Microblog startup [in /home/yoj/devman/microblog/app/__init__.py:59]
