2018-09-06 10:55:46,484 INFO: Microblog startup [in /home/yoj/devman/microblog/app/__init__.py:85]
2018-09-06 10:56:00,230 ERROR: Exception on / [GET] [in /home/yoj/devman/microblog/.venv/lib/python3.6/site-packages/flask/app.py:1761]
Traceback (most recent call last):
  File "/home/yoj/devman/microblog/.venv/lib/python3.6/site-packages/flask/app.py", line 2292, in wsgi_app
    response = self.full_dispatch_request()
  File "/home/yoj/devman/microblog/.venv/lib/python3.6/site-packages/flask/app.py", line 1815, in full_dispatch_request
    rv = self.handle_user_exception(e)
  File "/home/yoj/devman/microblog/.venv/lib/python3.6/site-packages/flask/app.py", line 1718, in handle_user_exception
    reraise(exc_type, exc_value, tb)
  File "/home/yoj/devman/microblog/.venv/lib/python3.6/site-packages/flask/_compat.py", line 35, in reraise
    raise value
  File "/home/yoj/devman/microblog/.venv/lib/python3.6/site-packages/flask/app.py", line 1811, in full_dispatch_request
    rv = self.preprocess_request()
  File "/home/yoj/devman/microblog/.venv/lib/python3.6/site-packages/flask/app.py", line 2087, in preprocess_request
    rv = func()
  File "/home/yoj/devman/microblog/app/main/routes.py", line 195, in before_request
    db.session.commit()
  File "/home/yoj/devman/microblog/.venv/lib/python3.6/site-packages/sqlalchemy/orm/scoping.py", line 153, in do
    return getattr(self.registry(), name)(*args, **kwargs)
  File "/home/yoj/devman/microblog/.venv/lib/python3.6/site-packages/sqlalchemy/orm/session.py", line 943, in commit
    self.transaction.commit()
  File "/home/yoj/devman/microblog/.venv/lib/python3.6/site-packages/sqlalchemy/orm/session.py", line 474, in commit
    self.session.dispatch.after_commit(self.session)
  File "/home/yoj/devman/microblog/.venv/lib/python3.6/site-packages/sqlalchemy/event/attr.py", line 246, in __call__
    fn(*args, **kw)
  File "/home/yoj/devman/microblog/app/models.py", line 37, in after_commit
    for obj in session._changes['add']:
TypeError: 'NoneType' object is not subscriptable
2018-09-06 10:59:09,058 INFO: Microblog startup [in /home/yoj/devman/microblog/app/__init__.py:85]
2018-09-06 10:59:13,658 ERROR: Exception on / [GET] [in /home/yoj/devman/microblog/.venv/lib/python3.6/site-packages/flask/app.py:1761]
Traceback (most recent call last):
  File "/home/yoj/devman/microblog/.venv/lib/python3.6/site-packages/flask/app.py", line 2292, in wsgi_app
    response = self.full_dispatch_request()
  File "/home/yoj/devman/microblog/.venv/lib/python3.6/site-packages/flask/app.py", line 1815, in full_dispatch_request
    rv = self.handle_user_exception(e)
  File "/home/yoj/devman/microblog/.venv/lib/python3.6/site-packages/flask/app.py", line 1718, in handle_user_exception
    reraise(exc_type, exc_value, tb)
  File "/home/yoj/devman/microblog/.venv/lib/python3.6/site-packages/flask/_compat.py", line 35, in reraise
    raise value
  File "/home/yoj/devman/microblog/.venv/lib/python3.6/site-packages/flask/app.py", line 1811, in full_dispatch_request
    rv = self.preprocess_request()
  File "/home/yoj/devman/microblog/.venv/lib/python3.6/site-packages/flask/app.py", line 2087, in preprocess_request
    rv = func()
  File "/home/yoj/devman/microblog/app/main/routes.py", line 195, in before_request
    db.session.commit()
  File "/home/yoj/devman/microblog/.venv/lib/python3.6/site-packages/sqlalchemy/orm/scoping.py", line 153, in do
    return getattr(self.registry(), name)(*args, **kwargs)
  File "/home/yoj/devman/microblog/.venv/lib/python3.6/site-packages/sqlalchemy/orm/session.py", line 943, in commit
    self.transaction.commit()
  File "/home/yoj/devman/microblog/.venv/lib/python3.6/site-packages/sqlalchemy/orm/session.py", line 474, in commit
    self.session.dispatch.after_commit(self.session)
  File "/home/yoj/devman/microblog/.venv/lib/python3.6/site-packages/sqlalchemy/event/attr.py", line 246, in __call__
    fn(*args, **kw)
  File "/home/yoj/devman/microblog/app/models.py", line 37, in after_commit
    print(isinstance(obj, SearchableMixin))
UnboundLocalError: local variable 'obj' referenced before assignment
2018-09-06 11:00:04,320 INFO: Microblog startup [in /home/yoj/devman/microblog/app/__init__.py:85]
2018-09-06 11:00:10,880 ERROR: Exception on / [GET] [in /home/yoj/devman/microblog/.venv/lib/python3.6/site-packages/flask/app.py:1761]
Traceback (most recent call last):
  File "/home/yoj/devman/microblog/.venv/lib/python3.6/site-packages/flask/app.py", line 2292, in wsgi_app
    response = self.full_dispatch_request()
  File "/home/yoj/devman/microblog/.venv/lib/python3.6/site-packages/flask/app.py", line 1815, in full_dispatch_request
    rv = self.handle_user_exception(e)
  File "/home/yoj/devman/microblog/.venv/lib/python3.6/site-packages/flask/app.py", line 1718, in handle_user_exception
    reraise(exc_type, exc_value, tb)
  File "/home/yoj/devman/microblog/.venv/lib/python3.6/site-packages/flask/_compat.py", line 35, in reraise
    raise value
  File "/home/yoj/devman/microblog/.venv/lib/python3.6/site-packages/flask/app.py", line 1811, in full_dispatch_request
    rv = self.preprocess_request()
  File "/home/yoj/devman/microblog/.venv/lib/python3.6/site-packages/flask/app.py", line 2087, in preprocess_request
    rv = func()
  File "/home/yoj/devman/microblog/app/main/routes.py", line 195, in before_request
    db.session.commit()
  File "/home/yoj/devman/microblog/.venv/lib/python3.6/site-packages/sqlalchemy/orm/scoping.py", line 153, in do
    return getattr(self.registry(), name)(*args, **kwargs)
  File "/home/yoj/devman/microblog/.venv/lib/python3.6/site-packages/sqlalchemy/orm/session.py", line 943, in commit
    self.transaction.commit()
  File "/home/yoj/devman/microblog/.venv/lib/python3.6/site-packages/sqlalchemy/orm/session.py", line 474, in commit
    self.session.dispatch.after_commit(self.session)
  File "/home/yoj/devman/microblog/.venv/lib/python3.6/site-packages/sqlalchemy/event/attr.py", line 246, in __call__
    fn(*args, **kw)
  File "/home/yoj/devman/microblog/app/models.py", line 38, in after_commit
    for obj in session._changes['add']:
TypeError: 'NoneType' object is not subscriptable
2018-09-06 11:01:36,437 INFO: Microblog startup [in /home/yoj/devman/microblog/app/__init__.py:85]
2018-09-06 11:01:38,871 ERROR: Exception on / [GET] [in /home/yoj/devman/microblog/.venv/lib/python3.6/site-packages/flask/app.py:1761]
Traceback (most recent call last):
  File "/home/yoj/devman/microblog/.venv/lib/python3.6/site-packages/flask/app.py", line 2292, in wsgi_app
    response = self.full_dispatch_request()
  File "/home/yoj/devman/microblog/.venv/lib/python3.6/site-packages/flask/app.py", line 1815, in full_dispatch_request
    rv = self.handle_user_exception(e)
  File "/home/yoj/devman/microblog/.venv/lib/python3.6/site-packages/flask/app.py", line 1718, in handle_user_exception
    reraise(exc_type, exc_value, tb)
  File "/home/yoj/devman/microblog/.venv/lib/python3.6/site-packages/flask/_compat.py", line 35, in reraise
    raise value
  File "/home/yoj/devman/microblog/.venv/lib/python3.6/site-packages/flask/app.py", line 1811, in full_dispatch_request
    rv = self.preprocess_request()
  File "/home/yoj/devman/microblog/.venv/lib/python3.6/site-packages/flask/app.py", line 2087, in preprocess_request
    rv = func()
  File "/home/yoj/devman/microblog/app/main/routes.py", line 195, in before_request
    db.session.commit()
  File "/home/yoj/devman/microblog/.venv/lib/python3.6/site-packages/sqlalchemy/orm/scoping.py", line 153, in do
    return getattr(self.registry(), name)(*args, **kwargs)
  File "/home/yoj/devman/microblog/.venv/lib/python3.6/site-packages/sqlalchemy/orm/session.py", line 943, in commit
    self.transaction.commit()
  File "/home/yoj/devman/microblog/.venv/lib/python3.6/site-packages/sqlalchemy/orm/session.py", line 474, in commit
    self.session.dispatch.after_commit(self.session)
  File "/home/yoj/devman/microblog/.venv/lib/python3.6/site-packages/sqlalchemy/event/attr.py", line 246, in __call__
    fn(*args, **kw)
  File "/home/yoj/devman/microblog/app/models.py", line 37, in after_commit
    print(session._changes['add'])
TypeError: 'NoneType' object is not subscriptable
2018-09-06 11:02:28,839 INFO: Microblog startup [in /home/yoj/devman/microblog/app/__init__.py:85]
