2018-08-23 13:31:01,402 ERROR: Exception on /user/vaska [GET] [in /home/belov/devman/microblog/.venv/lib/python3.6/site-packages/flask/app.py:1761]
Traceback (most recent call last):
  File "/home/belov/devman/microblog/.venv/lib/python3.6/site-packages/flask/app.py", line 2292, in wsgi_app
    response = self.full_dispatch_request()
  File "/home/belov/devman/microblog/.venv/lib/python3.6/site-packages/flask/app.py", line 1815, in full_dispatch_request
    rv = self.handle_user_exception(e)
  File "/home/belov/devman/microblog/.venv/lib/python3.6/site-packages/flask/app.py", line 1718, in handle_user_exception
    reraise(exc_type, exc_value, tb)
  File "/home/belov/devman/microblog/.venv/lib/python3.6/site-packages/flask/_compat.py", line 35, in reraise
    raise value
  File "/home/belov/devman/microblog/.venv/lib/python3.6/site-packages/flask/app.py", line 1813, in full_dispatch_request
    rv = self.dispatch_request()
  File "/home/belov/devman/microblog/.venv/lib/python3.6/site-packages/flask/app.py", line 1799, in dispatch_request
    return self.view_functions[rule.endpoint](**req.view_args)
  File "/home/belov/devman/microblog/.venv/lib/python3.6/site-packages/flask_login/utils.py", line 261, in decorated_view
    return func(*args, **kwargs)
  File "/home/belov/devman/microblog/app/routes.py", line 106, in user
    form=form,
NameError: name 'form' is not defined
2018-08-23 13:31:31,224 ERROR: Exception on /user/petka [GET] [in /home/belov/devman/microblog/.venv/lib/python3.6/site-packages/flask/app.py:1761]
Traceback (most recent call last):
  File "/home/belov/devman/microblog/.venv/lib/python3.6/site-packages/flask/app.py", line 2292, in wsgi_app
    response = self.full_dispatch_request()
  File "/home/belov/devman/microblog/.venv/lib/python3.6/site-packages/flask/app.py", line 1815, in full_dispatch_request
    rv = self.handle_user_exception(e)
  File "/home/belov/devman/microblog/.venv/lib/python3.6/site-packages/flask/app.py", line 1718, in handle_user_exception
    reraise(exc_type, exc_value, tb)
  File "/home/belov/devman/microblog/.venv/lib/python3.6/site-packages/flask/_compat.py", line 35, in reraise
    raise value
  File "/home/belov/devman/microblog/.venv/lib/python3.6/site-packages/flask/app.py", line 1813, in full_dispatch_request
    rv = self.dispatch_request()
  File "/home/belov/devman/microblog/.venv/lib/python3.6/site-packages/flask/app.py", line 1799, in dispatch_request
    return self.view_functions[rule.endpoint](**req.view_args)
  File "/home/belov/devman/microblog/.venv/lib/python3.6/site-packages/flask_login/utils.py", line 261, in decorated_view
    return func(*args, **kwargs)
  File "/home/belov/devman/microblog/app/routes.py", line 106, in user
    form=form,
NameError: name 'form' is not defined
2018-08-23 13:31:38,458 ERROR: Exception on /user/vaska [GET] [in /home/belov/devman/microblog/.venv/lib/python3.6/site-packages/flask/app.py:1761]
Traceback (most recent call last):
  File "/home/belov/devman/microblog/.venv/lib/python3.6/site-packages/flask/app.py", line 2292, in wsgi_app
    response = self.full_dispatch_request()
  File "/home/belov/devman/microblog/.venv/lib/python3.6/site-packages/flask/app.py", line 1815, in full_dispatch_request
    rv = self.handle_user_exception(e)
  File "/home/belov/devman/microblog/.venv/lib/python3.6/site-packages/flask/app.py", line 1718, in handle_user_exception
    reraise(exc_type, exc_value, tb)
  File "/home/belov/devman/microblog/.venv/lib/python3.6/site-packages/flask/_compat.py", line 35, in reraise
    raise value
  File "/home/belov/devman/microblog/.venv/lib/python3.6/site-packages/flask/app.py", line 1813, in full_dispatch_request
    rv = self.dispatch_request()
  File "/home/belov/devman/microblog/.venv/lib/python3.6/site-packages/flask/app.py", line 1799, in dispatch_request
    return self.view_functions[rule.endpoint](**req.view_args)
  File "/home/belov/devman/microblog/.venv/lib/python3.6/site-packages/flask_login/utils.py", line 261, in decorated_view
    return func(*args, **kwargs)
  File "/home/belov/devman/microblog/app/routes.py", line 106, in user
    form=form,
NameError: name 'form' is not defined
2018-08-23 13:31:44,567 ERROR: Exception on /user/vaska [GET] [in /home/belov/devman/microblog/.venv/lib/python3.6/site-packages/flask/app.py:1761]
Traceback (most recent call last):
  File "/home/belov/devman/microblog/.venv/lib/python3.6/site-packages/flask/app.py", line 2292, in wsgi_app
    response = self.full_dispatch_request()
  File "/home/belov/devman/microblog/.venv/lib/python3.6/site-packages/flask/app.py", line 1815, in full_dispatch_request
    rv = self.handle_user_exception(e)
  File "/home/belov/devman/microblog/.venv/lib/python3.6/site-packages/flask/app.py", line 1718, in handle_user_exception
    reraise(exc_type, exc_value, tb)
  File "/home/belov/devman/microblog/.venv/lib/python3.6/site-packages/flask/_compat.py", line 35, in reraise
    raise value
  File "/home/belov/devman/microblog/.venv/lib/python3.6/site-packages/flask/app.py", line 1813, in full_dispatch_request
    rv = self.dispatch_request()
  File "/home/belov/devman/microblog/.venv/lib/python3.6/site-packages/flask/app.py", line 1799, in dispatch_request
    return self.view_functions[rule.endpoint](**req.view_args)
  File "/home/belov/devman/microblog/.venv/lib/python3.6/site-packages/flask_login/utils.py", line 261, in decorated_view
    return func(*args, **kwargs)
  File "/home/belov/devman/microblog/app/routes.py", line 106, in user
    form=form,
NameError: name 'form' is not defined
2018-08-23 13:34:47,955 INFO: Microblog startup [in /home/belov/devman/microblog/app/__init__.py:45]
2018-08-23 13:34:50,899 ERROR: Exception on /user/vaska [GET] [in /home/belov/devman/microblog/.venv/lib/python3.6/site-packages/flask/app.py:1761]
Traceback (most recent call last):
  File "/home/belov/devman/microblog/.venv/lib/python3.6/site-packages/flask/app.py", line 2292, in wsgi_app
    response = self.full_dispatch_request()
  File "/home/belov/devman/microblog/.venv/lib/python3.6/site-packages/flask/app.py", line 1815, in full_dispatch_request
    rv = self.handle_user_exception(e)
  File "/home/belov/devman/microblog/.venv/lib/python3.6/site-packages/flask/app.py", line 1718, in handle_user_exception
    reraise(exc_type, exc_value, tb)
  File "/home/belov/devman/microblog/.venv/lib/python3.6/site-packages/flask/_compat.py", line 35, in reraise
    raise value
  File "/home/belov/devman/microblog/.venv/lib/python3.6/site-packages/flask/app.py", line 1813, in full_dispatch_request
    rv = self.dispatch_request()
  File "/home/belov/devman/microblog/.venv/lib/python3.6/site-packages/flask/app.py", line 1799, in dispatch_request
    return self.view_functions[rule.endpoint](**req.view_args)
  File "/home/belov/devman/microblog/.venv/lib/python3.6/site-packages/flask_login/utils.py", line 261, in decorated_view
    return func(*args, **kwargs)
  File "/home/belov/devman/microblog/app/routes.py", line 106, in user
    form=form,
NameError: name 'form' is not defined
2018-08-23 13:35:37,596 INFO: Microblog startup [in /home/belov/devman/microblog/app/__init__.py:45]
2018-08-23 13:35:56,958 INFO: Microblog startup [in /home/belov/devman/microblog/app/__init__.py:45]
2018-08-23 13:36:17,415 INFO: Microblog startup [in /home/belov/devman/microblog/app/__init__.py:45]
2018-08-23 13:37:12,080 INFO: Microblog startup [in /home/belov/devman/microblog/app/__init__.py:45]
2018-08-23 13:37:16,486 ERROR: Exception on /user/vaska [GET] [in /home/belov/devman/microblog/.venv/lib/python3.6/site-packages/flask/app.py:1761]
Traceback (most recent call last):
  File "/home/belov/devman/microblog/.venv/lib/python3.6/site-packages/flask/app.py", line 2292, in wsgi_app
    response = self.full_dispatch_request()
  File "/home/belov/devman/microblog/.venv/lib/python3.6/site-packages/flask/app.py", line 1815, in full_dispatch_request
    rv = self.handle_user_exception(e)
  File "/home/belov/devman/microblog/.venv/lib/python3.6/site-packages/flask/app.py", line 1718, in handle_user_exception
    reraise(exc_type, exc_value, tb)
  File "/home/belov/devman/microblog/.venv/lib/python3.6/site-packages/flask/_compat.py", line 35, in reraise
    raise value
  File "/home/belov/devman/microblog/.venv/lib/python3.6/site-packages/flask/app.py", line 1813, in full_dispatch_request
    rv = self.dispatch_request()
  File "/home/belov/devman/microblog/.venv/lib/python3.6/site-packages/flask/app.py", line 1799, in dispatch_request
    return self.view_functions[rule.endpoint](**req.view_args)
  File "/home/belov/devman/microblog/.venv/lib/python3.6/site-packages/flask_login/utils.py", line 261, in decorated_view
    return func(*args, **kwargs)
  File "/home/belov/devman/microblog/app/routes.py", line 101, in user
    next_url = url_for('user', page=posts.next_num) if posts.has_next else None
  File "/home/belov/devman/microblog/.venv/lib/python3.6/site-packages/flask/helpers.py", line 356, in url_for
    return appctx.app.handle_url_build_error(error, endpoint, values)
  File "/home/belov/devman/microblog/.venv/lib/python3.6/site-packages/flask/app.py", line 2061, in handle_url_build_error
    reraise(exc_type, exc_value, tb)
  File "/home/belov/devman/microblog/.venv/lib/python3.6/site-packages/flask/_compat.py", line 35, in reraise
    raise value
  File "/home/belov/devman/microblog/.venv/lib/python3.6/site-packages/flask/helpers.py", line 345, in url_for
    force_external=external)
  File "/home/belov/devman/microblog/.venv/lib/python3.6/site-packages/werkzeug/routing.py", line 1776, in build
    raise BuildError(endpoint, values, method, self)
werkzeug.routing.BuildError: Could not build url for endpoint 'user' with values ['page']. Did you forget to specify values ['username']?
2018-08-23 13:38:00,306 INFO: Microblog startup [in /home/belov/devman/microblog/app/__init__.py:45]
