2018-09-04 14:32:46,728 ERROR: Exception on /edit_profile [POST] [in /home/yoj/devman/microblog/.venv/lib/python3.6/site-packages/flask/app.py:1761]
Traceback (most recent call last):
  File "/home/yoj/devman/microblog/.venv/lib/python3.6/site-packages/sqlalchemy/engine/base.py", line 1193, in _execute_context
    context)
  File "/home/yoj/devman/microblog/.venv/lib/python3.6/site-packages/sqlalchemy/engine/default.py", line 509, in do_execute
    cursor.execute(statement, parameters)
sqlite3.InterfaceError: Error binding parameter 0 - probably unsupported type.

The above exception was the direct cause of the following exception:

Traceback (most recent call last):
  File "/home/yoj/devman/microblog/.venv/lib/python3.6/site-packages/flask/app.py", line 2292, in wsgi_app
    response = self.full_dispatch_request()
  File "/home/yoj/devman/microblog/.venv/lib/python3.6/site-packages/flask/app.py", line 1815, in full_dispatch_request
    rv = self.handle_user_exception(e)
  File "/home/yoj/devman/microblog/.venv/lib/python3.6/site-packages/flask/app.py", line 1718, in handle_user_exception
    reraise(exc_type, exc_value, tb)
  File "/home/yoj/devman/microblog/.venv/lib/python3.6/site-packages/flask/_compat.py", line 35, in reraise
    raise value
  File "/home/yoj/devman/microblog/.venv/lib/python3.6/site-packages/flask/app.py", line 1813, in full_dispatch_request
    rv = self.dispatch_request()
  File "/home/yoj/devman/microblog/.venv/lib/python3.6/site-packages/flask/app.py", line 1799, in dispatch_request
    return self.view_functions[rule.endpoint](**req.view_args)
  File "/home/yoj/devman/microblog/.venv/lib/python3.6/site-packages/flask_login/utils.py", line 261, in decorated_view
    return func(*args, **kwargs)
  File "/home/yoj/devman/microblog/app/routes.py", line 145, in edit_profile
    db.session.commit()
  File "/home/yoj/devman/microblog/.venv/lib/python3.6/site-packages/sqlalchemy/orm/scoping.py", line 153, in do
    return getattr(self.registry(), name)(*args, **kwargs)
  File "/home/yoj/devman/microblog/.venv/lib/python3.6/site-packages/sqlalchemy/orm/session.py", line 943, in commit
    self.transaction.commit()
  File "/home/yoj/devman/microblog/.venv/lib/python3.6/site-packages/sqlalchemy/orm/session.py", line 467, in commit
    self._prepare_impl()
  File "/home/yoj/devman/microblog/.venv/lib/python3.6/site-packages/sqlalchemy/orm/session.py", line 447, in _prepare_impl
    self.session.flush()
  File "/home/yoj/devman/microblog/.venv/lib/python3.6/site-packages/sqlalchemy/orm/session.py", line 2254, in flush
    self._flush(objects)
  File "/home/yoj/devman/microblog/.venv/lib/python3.6/site-packages/sqlalchemy/orm/session.py", line 2380, in _flush
    transaction.rollback(_capture_exception=True)
  File "/home/yoj/devman/microblog/.venv/lib/python3.6/site-packages/sqlalchemy/util/langhelpers.py", line 66, in __exit__
    compat.reraise(exc_type, exc_value, exc_tb)
  File "/home/yoj/devman/microblog/.venv/lib/python3.6/site-packages/sqlalchemy/util/compat.py", line 249, in reraise
    raise value
  File "/home/yoj/devman/microblog/.venv/lib/python3.6/site-packages/sqlalchemy/orm/session.py", line 2344, in _flush
    flush_context.execute()
  File "/home/yoj/devman/microblog/.venv/lib/python3.6/site-packages/sqlalchemy/orm/unitofwork.py", line 391, in execute
    rec.execute(self)
  File "/home/yoj/devman/microblog/.venv/lib/python3.6/site-packages/sqlalchemy/orm/unitofwork.py", line 556, in execute
    uow
  File "/home/yoj/devman/microblog/.venv/lib/python3.6/site-packages/sqlalchemy/orm/persistence.py", line 177, in save_obj
    mapper, table, update)
  File "/home/yoj/devman/microblog/.venv/lib/python3.6/site-packages/sqlalchemy/orm/persistence.py", line 768, in _emit_update_statements
    execute(statement, multiparams)
  File "/home/yoj/devman/microblog/.venv/lib/python3.6/site-packages/sqlalchemy/engine/base.py", line 948, in execute
    return meth(self, multiparams, params)
  File "/home/yoj/devman/microblog/.venv/lib/python3.6/site-packages/sqlalchemy/sql/elements.py", line 269, in _execute_on_connection
    return connection._execute_clauseelement(self, multiparams, params)
  File "/home/yoj/devman/microblog/.venv/lib/python3.6/site-packages/sqlalchemy/engine/base.py", line 1060, in _execute_clauseelement
    compiled_sql, distilled_params
  File "/home/yoj/devman/microblog/.venv/lib/python3.6/site-packages/sqlalchemy/engine/base.py", line 1200, in _execute_context
    context)
  File "/home/yoj/devman/microblog/.venv/lib/python3.6/site-packages/sqlalchemy/engine/base.py", line 1413, in _handle_dbapi_exception
    exc_info
  File "/home/yoj/devman/microblog/.venv/lib/python3.6/site-packages/sqlalchemy/util/compat.py", line 265, in raise_from_cause
    reraise(type(exception), exception, tb=exc_tb, cause=cause)
  File "/home/yoj/devman/microblog/.venv/lib/python3.6/site-packages/sqlalchemy/util/compat.py", line 248, in reraise
    raise value.with_traceback(tb)
  File "/home/yoj/devman/microblog/.venv/lib/python3.6/site-packages/sqlalchemy/engine/base.py", line 1193, in _execute_context
    context)
  File "/home/yoj/devman/microblog/.venv/lib/python3.6/site-packages/sqlalchemy/engine/default.py", line 509, in do_execute
    cursor.execute(statement, parameters)
sqlalchemy.exc.InterfaceError: (sqlite3.InterfaceError) Error binding parameter 0 - probably unsupported type. [SQL: 'UPDATE user SET photo_path=? WHERE user.id = ?'] [parameters: (<FileStorage: 'muay.jpg' ('image/jpeg')>, 3)] (Background on this error at: http://sqlalche.me/e/rvf5)
2018-09-04 14:34:28,690 INFO: Microblog startup [in /home/yoj/devman/microblog/app/__init__.py:59]
2018-09-04 14:37:14,224 INFO: Microblog startup [in /home/yoj/devman/microblog/app/__init__.py:59]
2018-09-04 14:39:38,494 INFO: Microblog startup [in /home/yoj/devman/microblog/app/__init__.py:59]
2018-09-04 14:41:34,805 INFO: Microblog startup [in /home/yoj/devman/microblog/app/__init__.py:59]
2018-09-04 14:43:53,571 INFO: Microblog startup [in /home/yoj/devman/microblog/app/__init__.py:59]
2018-09-04 14:43:59,500 ERROR: Exception on /edit_profile [GET] [in /home/yoj/devman/microblog/.venv/lib/python3.6/site-packages/flask/app.py:1761]
Traceback (most recent call last):
  File "/home/yoj/devman/microblog/.venv/lib/python3.6/site-packages/flask/app.py", line 2292, in wsgi_app
    response = self.full_dispatch_request()
  File "/home/yoj/devman/microblog/.venv/lib/python3.6/site-packages/flask/app.py", line 1815, in full_dispatch_request
    rv = self.handle_user_exception(e)
  File "/home/yoj/devman/microblog/.venv/lib/python3.6/site-packages/flask/app.py", line 1718, in handle_user_exception
    reraise(exc_type, exc_value, tb)
  File "/home/yoj/devman/microblog/.venv/lib/python3.6/site-packages/flask/_compat.py", line 35, in reraise
    raise value
  File "/home/yoj/devman/microblog/.venv/lib/python3.6/site-packages/flask/app.py", line 1813, in full_dispatch_request
    rv = self.dispatch_request()
  File "/home/yoj/devman/microblog/.venv/lib/python3.6/site-packages/flask/app.py", line 1799, in dispatch_request
    return self.view_functions[rule.endpoint](**req.view_args)
  File "/home/yoj/devman/microblog/.venv/lib/python3.6/site-packages/flask_login/utils.py", line 261, in decorated_view
    return func(*args, **kwargs)
  File "/home/yoj/devman/microblog/app/routes.py", line 152, in edit_profile
    return render_template('edit_profile.html', title='Edit Profile', form=form, user=user, filepath=filepath)
UnboundLocalError: local variable 'filepath' referenced before assignment
2018-09-04 14:46:30,007 INFO: Microblog startup [in /home/yoj/devman/microblog/app/__init__.py:59]
2018-09-04 14:46:34,202 ERROR: Exception on /edit_profile [GET] [in /home/yoj/devman/microblog/.venv/lib/python3.6/site-packages/flask/app.py:1761]
Traceback (most recent call last):
  File "/home/yoj/devman/microblog/.venv/lib/python3.6/site-packages/flask/app.py", line 2292, in wsgi_app
    response = self.full_dispatch_request()
  File "/home/yoj/devman/microblog/.venv/lib/python3.6/site-packages/flask/app.py", line 1815, in full_dispatch_request
    rv = self.handle_user_exception(e)
  File "/home/yoj/devman/microblog/.venv/lib/python3.6/site-packages/flask/app.py", line 1718, in handle_user_exception
    reraise(exc_type, exc_value, tb)
  File "/home/yoj/devman/microblog/.venv/lib/python3.6/site-packages/flask/_compat.py", line 35, in reraise
    raise value
  File "/home/yoj/devman/microblog/.venv/lib/python3.6/site-packages/flask/app.py", line 1813, in full_dispatch_request
    rv = self.dispatch_request()
  File "/home/yoj/devman/microblog/.venv/lib/python3.6/site-packages/flask/app.py", line 1799, in dispatch_request
    return self.view_functions[rule.endpoint](**req.view_args)
  File "/home/yoj/devman/microblog/.venv/lib/python3.6/site-packages/flask_login/utils.py", line 261, in decorated_view
    return func(*args, **kwargs)
  File "/home/yoj/devman/microblog/app/routes.py", line 153, in edit_profile
    return render_template('edit_profile.html', title='Edit Profile', form=form, user=user, filepath=filepath)
UnboundLocalError: local variable 'filepath' referenced before assignment
2018-09-04 14:47:36,589 INFO: Microblog startup [in /home/yoj/devman/microblog/app/__init__.py:59]
2018-09-04 14:51:01,195 INFO: Microblog startup [in /home/yoj/devman/microblog/app/__init__.py:59]
2018-09-04 14:52:08,274 INFO: Microblog startup [in /home/yoj/devman/microblog/app/__init__.py:59]
2018-09-04 14:53:21,066 INFO: Microblog startup [in /home/yoj/devman/microblog/app/__init__.py:59]
2018-09-04 14:53:52,953 INFO: Microblog startup [in /home/yoj/devman/microblog/app/__init__.py:59]
