2018-09-06 10:14:32,721 ERROR: Exception on /index [GET] [in /home/yoj/devman/microblog/.venv/lib/python3.6/site-packages/flask/app.py:1761]
Traceback (most recent call last):
  File "/home/yoj/devman/microblog/.venv/lib/python3.6/site-packages/flask/app.py", line 2292, in wsgi_app
    response = self.full_dispatch_request()
  File "/home/yoj/devman/microblog/.venv/lib/python3.6/site-packages/flask/app.py", line 1815, in full_dispatch_request
    rv = self.handle_user_exception(e)
  File "/home/yoj/devman/microblog/.venv/lib/python3.6/site-packages/flask/app.py", line 1718, in handle_user_exception
    reraise(exc_type, exc_value, tb)
  File "/home/yoj/devman/microblog/.venv/lib/python3.6/site-packages/flask/_compat.py", line 35, in reraise
    raise value
  File "/home/yoj/devman/microblog/.venv/lib/python3.6/site-packages/flask/app.py", line 1811, in full_dispatch_request
    rv = self.preprocess_request()
  File "/home/yoj/devman/microblog/.venv/lib/python3.6/site-packages/flask/app.py", line 2087, in preprocess_request
    rv = func()
  File "/home/yoj/devman/microblog/app/main/routes.py", line 31, in before_request
    db.session.commit()
  File "/home/yoj/devman/microblog/.venv/lib/python3.6/site-packages/sqlalchemy/orm/scoping.py", line 153, in do
    return getattr(self.registry(), name)(*args, **kwargs)
  File "/home/yoj/devman/microblog/.venv/lib/python3.6/site-packages/sqlalchemy/orm/session.py", line 943, in commit
    self.transaction.commit()
  File "/home/yoj/devman/microblog/.venv/lib/python3.6/site-packages/sqlalchemy/orm/session.py", line 474, in commit
    self.session.dispatch.after_commit(self.session)
  File "/home/yoj/devman/microblog/.venv/lib/python3.6/site-packages/sqlalchemy/event/attr.py", line 246, in __call__
    fn(*args, **kw)
  File "/home/yoj/devman/microblog/app/models.py", line 35, in after_commit
    for obj in session._changes['add']:
TypeError: 'NoneType' object is not subscriptable
2018-09-06 10:18:07,849 INFO: Microblog startup [in /home/yoj/devman/microblog/app/__init__.py:85]
2018-09-06 10:18:11,655 ERROR: Exception on /index [GET] [in /home/yoj/devman/microblog/.venv/lib/python3.6/site-packages/flask/app.py:1761]
Traceback (most recent call last):
  File "/home/yoj/devman/microblog/.venv/lib/python3.6/site-packages/flask/app.py", line 2292, in wsgi_app
    response = self.full_dispatch_request()
  File "/home/yoj/devman/microblog/.venv/lib/python3.6/site-packages/flask/app.py", line 1815, in full_dispatch_request
    rv = self.handle_user_exception(e)
  File "/home/yoj/devman/microblog/.venv/lib/python3.6/site-packages/flask/app.py", line 1718, in handle_user_exception
    reraise(exc_type, exc_value, tb)
  File "/home/yoj/devman/microblog/.venv/lib/python3.6/site-packages/flask/_compat.py", line 35, in reraise
    raise value
  File "/home/yoj/devman/microblog/.venv/lib/python3.6/site-packages/flask/app.py", line 1811, in full_dispatch_request
    rv = self.preprocess_request()
  File "/home/yoj/devman/microblog/.venv/lib/python3.6/site-packages/flask/app.py", line 2087, in preprocess_request
    rv = func()
  File "/home/yoj/devman/microblog/app/main/routes.py", line 31, in before_request
    db.session.commit()
  File "/home/yoj/devman/microblog/.venv/lib/python3.6/site-packages/sqlalchemy/orm/scoping.py", line 153, in do
    return getattr(self.registry(), name)(*args, **kwargs)
  File "/home/yoj/devman/microblog/.venv/lib/python3.6/site-packages/sqlalchemy/orm/session.py", line 943, in commit
    self.transaction.commit()
  File "/home/yoj/devman/microblog/.venv/lib/python3.6/site-packages/sqlalchemy/orm/session.py", line 474, in commit
    self.session.dispatch.after_commit(self.session)
  File "/home/yoj/devman/microblog/.venv/lib/python3.6/site-packages/sqlalchemy/event/attr.py", line 246, in __call__
    fn(*args, **kw)
  File "/home/yoj/devman/microblog/app/models.py", line 36, in after_commit
    for obj in session._changes['add']:
TypeError: 'NoneType' object is not subscriptable
2018-09-06 10:22:50,650 INFO: Microblog startup [in /home/yoj/devman/microblog/app/__init__.py:85]
2018-09-06 10:22:53,400 ERROR: Exception on / [GET] [in /home/yoj/devman/microblog/.venv/lib/python3.6/site-packages/flask/app.py:1761]
Traceback (most recent call last):
  File "/home/yoj/devman/microblog/.venv/lib/python3.6/site-packages/flask/app.py", line 2292, in wsgi_app
    response = self.full_dispatch_request()
  File "/home/yoj/devman/microblog/.venv/lib/python3.6/site-packages/flask/app.py", line 1815, in full_dispatch_request
    rv = self.handle_user_exception(e)
  File "/home/yoj/devman/microblog/.venv/lib/python3.6/site-packages/flask/app.py", line 1718, in handle_user_exception
    reraise(exc_type, exc_value, tb)
  File "/home/yoj/devman/microblog/.venv/lib/python3.6/site-packages/flask/_compat.py", line 35, in reraise
    raise value
  File "/home/yoj/devman/microblog/.venv/lib/python3.6/site-packages/flask/app.py", line 1811, in full_dispatch_request
    rv = self.preprocess_request()
  File "/home/yoj/devman/microblog/.venv/lib/python3.6/site-packages/flask/app.py", line 2087, in preprocess_request
    rv = func()
  File "/home/yoj/devman/microblog/app/main/routes.py", line 32, in before_request
    db.session.commit()
  File "/home/yoj/devman/microblog/.venv/lib/python3.6/site-packages/sqlalchemy/orm/scoping.py", line 153, in do
    return getattr(self.registry(), name)(*args, **kwargs)
  File "/home/yoj/devman/microblog/.venv/lib/python3.6/site-packages/sqlalchemy/orm/session.py", line 943, in commit
    self.transaction.commit()
  File "/home/yoj/devman/microblog/.venv/lib/python3.6/site-packages/sqlalchemy/orm/session.py", line 474, in commit
    self.session.dispatch.after_commit(self.session)
  File "/home/yoj/devman/microblog/.venv/lib/python3.6/site-packages/sqlalchemy/event/attr.py", line 246, in __call__
    fn(*args, **kw)
  File "/home/yoj/devman/microblog/app/models.py", line 36, in after_commit
    for obj in session._changes['add']:
TypeError: 'NoneType' object is not subscriptable
2018-09-06 10:29:18,031 INFO: Microblog startup [in /home/yoj/devman/microblog/app/__init__.py:85]
2018-09-06 10:29:24,074 ERROR: Exception on / [GET] [in /home/yoj/devman/microblog/.venv/lib/python3.6/site-packages/flask/app.py:1761]
Traceback (most recent call last):
  File "/home/yoj/devman/microblog/.venv/lib/python3.6/site-packages/flask/app.py", line 2292, in wsgi_app
    response = self.full_dispatch_request()
  File "/home/yoj/devman/microblog/.venv/lib/python3.6/site-packages/flask/app.py", line 1815, in full_dispatch_request
    rv = self.handle_user_exception(e)
  File "/home/yoj/devman/microblog/.venv/lib/python3.6/site-packages/flask/app.py", line 1718, in handle_user_exception
    reraise(exc_type, exc_value, tb)
  File "/home/yoj/devman/microblog/.venv/lib/python3.6/site-packages/flask/_compat.py", line 35, in reraise
    raise value
  File "/home/yoj/devman/microblog/.venv/lib/python3.6/site-packages/flask/app.py", line 1811, in full_dispatch_request
    rv = self.preprocess_request()
  File "/home/yoj/devman/microblog/.venv/lib/python3.6/site-packages/flask/app.py", line 2087, in preprocess_request
    rv = func()
  File "/home/yoj/devman/microblog/app/main/routes.py", line 33, in before_request
    db.session.commit()
  File "/home/yoj/devman/microblog/.venv/lib/python3.6/site-packages/sqlalchemy/orm/scoping.py", line 153, in do
    return getattr(self.registry(), name)(*args, **kwargs)
  File "/home/yoj/devman/microblog/.venv/lib/python3.6/site-packages/sqlalchemy/orm/session.py", line 943, in commit
    self.transaction.commit()
  File "/home/yoj/devman/microblog/.venv/lib/python3.6/site-packages/sqlalchemy/orm/session.py", line 474, in commit
    self.session.dispatch.after_commit(self.session)
  File "/home/yoj/devman/microblog/.venv/lib/python3.6/site-packages/sqlalchemy/event/attr.py", line 246, in __call__
    fn(*args, **kw)
  File "/home/yoj/devman/microblog/app/models.py", line 36, in after_commit
    for obj in session._changes['add']:
TypeError: 'NoneType' object is not subscriptable
2018-09-06 10:30:20,286 INFO: Microblog startup [in /home/yoj/devman/microblog/app/__init__.py:85]
2018-09-06 10:30:21,944 ERROR: Exception on / [GET] [in /home/yoj/devman/microblog/.venv/lib/python3.6/site-packages/flask/app.py:1761]
Traceback (most recent call last):
  File "/home/yoj/devman/microblog/.venv/lib/python3.6/site-packages/flask/app.py", line 2292, in wsgi_app
    response = self.full_dispatch_request()
  File "/home/yoj/devman/microblog/.venv/lib/python3.6/site-packages/flask/app.py", line 1815, in full_dispatch_request
    rv = self.handle_user_exception(e)
  File "/home/yoj/devman/microblog/.venv/lib/python3.6/site-packages/flask/app.py", line 1718, in handle_user_exception
    reraise(exc_type, exc_value, tb)
  File "/home/yoj/devman/microblog/.venv/lib/python3.6/site-packages/flask/_compat.py", line 35, in reraise
    raise value
  File "/home/yoj/devman/microblog/.venv/lib/python3.6/site-packages/flask/app.py", line 1811, in full_dispatch_request
    rv = self.preprocess_request()
  File "/home/yoj/devman/microblog/.venv/lib/python3.6/site-packages/flask/app.py", line 2087, in preprocess_request
    rv = func()
  File "/home/yoj/devman/microblog/app/main/routes.py", line 33, in before_request
    db.session.commit()
  File "/home/yoj/devman/microblog/.venv/lib/python3.6/site-packages/sqlalchemy/orm/scoping.py", line 153, in do
    return getattr(self.registry(), name)(*args, **kwargs)
  File "/home/yoj/devman/microblog/.venv/lib/python3.6/site-packages/sqlalchemy/orm/session.py", line 943, in commit
    self.transaction.commit()
  File "/home/yoj/devman/microblog/.venv/lib/python3.6/site-packages/sqlalchemy/orm/session.py", line 474, in commit
    self.session.dispatch.after_commit(self.session)
  File "/home/yoj/devman/microblog/.venv/lib/python3.6/site-packages/sqlalchemy/event/attr.py", line 246, in __call__
    fn(*args, **kw)
  File "/home/yoj/devman/microblog/app/models.py", line 37, in after_commit
    for obj in session._changes['add']:
TypeError: 'NoneType' object is not subscriptable
