2018-08-23 13:38:09,921 ERROR: Exception on /user/vaska [GET] [in /home/belov/devman/microblog/.venv/lib/python3.6/site-packages/flask/app.py:1761]
Traceback (most recent call last):
  File "/home/belov/devman/microblog/.venv/lib/python3.6/site-packages/flask/app.py", line 2292, in wsgi_app
    response = self.full_dispatch_request()
  File "/home/belov/devman/microblog/.venv/lib/python3.6/site-packages/flask/app.py", line 1815, in full_dispatch_request
    rv = self.handle_user_exception(e)
  File "/home/belov/devman/microblog/.venv/lib/python3.6/site-packages/flask/app.py", line 1718, in handle_user_exception
    reraise(exc_type, exc_value, tb)
  File "/home/belov/devman/microblog/.venv/lib/python3.6/site-packages/flask/_compat.py", line 35, in reraise
    raise value
  File "/home/belov/devman/microblog/.venv/lib/python3.6/site-packages/flask/app.py", line 1813, in full_dispatch_request
    rv = self.dispatch_request()
  File "/home/belov/devman/microblog/.venv/lib/python3.6/site-packages/flask/app.py", line 1799, in dispatch_request
    return self.view_functions[rule.endpoint](**req.view_args)
  File "/home/belov/devman/microblog/.venv/lib/python3.6/site-packages/flask_login/utils.py", line 261, in decorated_view
    return func(*args, **kwargs)
  File "/home/belov/devman/microblog/app/routes.py", line 101, in user
    next_url = url_for('user', page=posts.next_num) if posts.has_next else None
  File "/home/belov/devman/microblog/.venv/lib/python3.6/site-packages/flask/helpers.py", line 356, in url_for
    return appctx.app.handle_url_build_error(error, endpoint, values)
  File "/home/belov/devman/microblog/.venv/lib/python3.6/site-packages/flask/app.py", line 2061, in handle_url_build_error
    reraise(exc_type, exc_value, tb)
  File "/home/belov/devman/microblog/.venv/lib/python3.6/site-packages/flask/_compat.py", line 35, in reraise
    raise value
  File "/home/belov/devman/microblog/.venv/lib/python3.6/site-packages/flask/helpers.py", line 345, in url_for
    force_external=external)
  File "/home/belov/devman/microblog/.venv/lib/python3.6/site-packages/werkzeug/routing.py", line 1776, in build
    raise BuildError(endpoint, values, method, self)
werkzeug.routing.BuildError: Could not build url for endpoint 'user' with values ['page']. Did you forget to specify values ['username']?
2018-08-23 13:38:56,249 INFO: Microblog startup [in /home/belov/devman/microblog/app/__init__.py:45]
2018-08-23 17:28:55,512 INFO: Microblog startup [in /home/belov/devman/microblog/app/__init__.py:46]
2018-08-23 17:30:05,492 INFO: Microblog startup [in /home/belov/devman/microblog/app/__init__.py:46]
2018-08-26 09:43:54,569 INFO: Microblog startup [in /home/yoj/devman/microblog/app/__init__.py:46]
2018-08-26 17:11:59,950 INFO: Microblog startup [in /home/yoj/devman/microblog/app/__init__.py:46]
2018-08-26 17:19:11,259 INFO: Microblog startup [in /home/yoj/devman/microblog/app/__init__.py:46]
2018-08-26 17:20:01,519 ERROR: Exception on /reset_password_request [POST] [in /home/yoj/devman/microblog/.venv/lib/python3.6/site-packages/flask/app.py:1761]
Traceback (most recent call last):
  File "/home/yoj/devman/microblog/.venv/lib/python3.6/site-packages/flask/app.py", line 2292, in wsgi_app
    response = self.full_dispatch_request()
  File "/home/yoj/devman/microblog/.venv/lib/python3.6/site-packages/flask/app.py", line 1815, in full_dispatch_request
    rv = self.handle_user_exception(e)
  File "/home/yoj/devman/microblog/.venv/lib/python3.6/site-packages/flask/app.py", line 1718, in handle_user_exception
    reraise(exc_type, exc_value, tb)
  File "/home/yoj/devman/microblog/.venv/lib/python3.6/site-packages/flask/_compat.py", line 35, in reraise
    raise value
  File "/home/yoj/devman/microblog/.venv/lib/python3.6/site-packages/flask/app.py", line 1813, in full_dispatch_request
    rv = self.dispatch_request()
  File "/home/yoj/devman/microblog/.venv/lib/python3.6/site-packages/flask/app.py", line 1799, in dispatch_request
    return self.view_functions[rule.endpoint](**req.view_args)
  File "/home/yoj/devman/microblog/app/routes.py", line 175, in reset_password_request
    send_password_reset_email(user)
  File "/home/yoj/devman/microblog/app/email.py", line 23, in send_password_reset_email
    sender=app.congig['ADMINS'][0],
AttributeError: 'Flask' object has no attribute 'congig'
2018-08-26 17:21:02,626 INFO: Microblog startup [in /home/yoj/devman/microblog/app/__init__.py:46]
2018-08-26 17:22:42,563 INFO: Microblog startup [in /home/yoj/devman/microblog/app/__init__.py:46]
2018-08-26 17:27:49,997 INFO: Microblog startup [in /home/yoj/devman/microblog/app/__init__.py:46]
2018-08-26 17:29:18,591 INFO: Microblog startup [in /home/yoj/devman/microblog/app/__init__.py:46]
2018-08-26 17:31:47,520 INFO: Microblog startup [in /home/yoj/devman/microblog/app/__init__.py:46]
2018-08-26 18:02:57,889 INFO: Microblog startup [in /home/yoj/devman/microblog/app/__init__.py:48]
2018-08-26 18:05:36,858 INFO: Microblog startup [in /home/yoj/devman/microblog/app/__init__.py:48]
